<?xml version="1.0" ?>
<robot name="art_bot" xmlns:xacro="http://ros.org/wiki/xacro">
  <material name="yellow">
    <color rgba="0.8 0.8 0.0 1.0"/>
  </material>
  <material name="black">
    <color rgba="0.15 0.15 0.15 1.0"/>
  </material>
  <material name="dark_grey">
    <color rgba="0.2 0.2 0.2 1.0"/>
  </material>
  <material name="light_grey">
    <color rgba="0.4 0.4 0.4 1.0"/>
  </material>
  <link name="base_footprint"/>
  <joint name="base_link_joint" type="fixed">
    <origin rpy="0 0 0" xyz="0 0 0.05"/>
    <parent link="base_footprint"/>
    <child link="base_link"/>
  </joint>
  <link name="base_link">
    <visual>
      <origin rpy="0 0 0" xyz="0 0 0"/>
      <geometry>
        <mesh filename="package://artbot_pkg/meshes/base_link.STL" scale="0.001 0.001 0.001"/>
      </geometry>
      <material name="yellow"/>
    </visual>
    <collision>
      <origin xyz="0 0 0"/>
      <geometry>
        <mesh filename="package://artbot_pkg/meshes/base_link_collision.STL" scale="0.001 0.001 0.001"/>
      </geometry>
    </collision>
    <inertial>
      <!-- Inertia from CAD model, filled box assumption -->
      <origin rpy="0 0 0" xyz="-0.01103 0 0.002"/>
      <mass value="2.844"/>
      <inertia ixx="0.018819942" ixy="0" ixz="-0.000101519" iyy="0.057333716" iyz="0" izz="0.074201740"/>
    </inertial>
  </link>
  <joint name="upper_left_wheel_shaft_joint" type="fixed">
    <origin rpy="0 0 0" xyz="0.150 0.108 0.0"/>
    <parent link="base_link"/>
    <child link="upper_left_wheel_shaft"/>
  </joint>
  <link name="upper_left_wheel_shaft">
    <visual>
      <origin rpy="0 0 0" xyz="0 0 0"/>
      <geometry>
        <mesh filename="package://artbot_pkg/meshes/wheel_shaft.STL" scale="0.001 0.001 0.001"/>
      </geometry>
      <material name="black"/>
    </visual>
    <collision>
      <origin xyz="0 0 0"/>
      <geometry>
        <mesh filename="package://artbot_pkg/meshes/wheel_shaft.STL" scale="0.001 0.001 0.001"/>
      </geometry>
    </collision>
    <inertial>
      <origin rpy="0 0 0" xyz="0 0.01221 0"/>
      <mass value="0.055"/>
      <inertia ixx="0.000021370" ixy="0" ixz="0" iyy="0.000009966" iyz="0" izz="0.000021370"/>
    </inertial>
  </link>
  <joint name="lower_left_wheel_shaft_joint" type="fixed">
    <origin rpy="0 0 0" xyz="-0.150 0.108 0.0"/>
    <parent link="base_link"/>
    <child link="lower_left_wheel_shaft"/>
  </joint>
  <link name="lower_left_wheel_shaft">
    <visual>
      <origin rpy="0 0 0" xyz="0 0 0"/>
      <geometry>
        <mesh filename="package://artbot_pkg/meshes/wheel_shaft.STL" scale="0.001 0.001 0.001"/>
      </geometry>
      <material name="black"/>
    </visual>
    <collision>
      <origin xyz="0 0 0"/>
      <geometry>
        <mesh filename="package://artbot_pkg/meshes/wheel_shaft.STL" scale="0.001 0.001 0.001"/>
      </geometry>
    </collision>
    <inertial>
      <origin rpy="0 0 0" xyz="0 0.01221 0"/>
      <mass value="0.055"/>
      <inertia ixx="0.000021370" ixy="0" ixz="0" iyy="0.000009966" iyz="0" izz="0.000021370"/>
    </inertial>
  </link>
  <joint name="upper_right_wheel_shaft_joint" type="fixed">
    <origin rpy="3.14159265359 0 0" xyz="0.150 -0.108 0.0"/>
    <parent link="base_link"/>
    <child link="upper_right_wheel_shaft"/>
  </joint>
  <link name="upper_right_wheel_shaft">
    <visual>
      <origin rpy="0 0 0" xyz="0 0 0"/>
      <geometry>
        <mesh filename="package://artbot_pkg/meshes/wheel_shaft.STL" scale="0.001 0.001 0.001"/>
      </geometry>
      <material name="black"/>
    </visual>
    <collision>
      <origin xyz="0 0 0"/>
      <geometry>
        <mesh filename="package://artbot_pkg/meshes/wheel_shaft.STL" scale="0.001 0.001 0.001"/>
      </geometry>
    </collision>
    <inertial>
      <origin rpy="0 0 0" xyz="0 0.01221 0"/>
      <mass value="0.055"/>
      <inertia ixx="0.000021370" ixy="0" ixz="0" iyy="0.000009966" iyz="0" izz="0.000021370"/>
    </inertial>
  </link>
  <joint name="lower_right_wheel_shaft_joint" type="fixed">
    <origin rpy="3.14159265359 0 0" xyz="-0.150 -0.108 0.0"/>
    <parent link="base_link"/>
    <child link="lower_right_wheel_shaft"/>
  </joint>
  <link name="lower_right_wheel_shaft">
    <visual>
      <origin rpy="0 0 0" xyz="0 0 0"/>
      <geometry>
        <mesh filename="package://artbot_pkg/meshes/wheel_shaft.STL" scale="0.001 0.001 0.001"/>
      </geometry>
      <material name="black"/>
    </visual>
    <collision>
      <origin xyz="0 0 0"/>
      <geometry>
        <mesh filename="package://artbot_pkg/meshes/wheel_shaft.STL" scale="0.001 0.001 0.001"/>
      </geometry>
    </collision>
    <inertial>
      <origin rpy="0 0 0" xyz="0 0.01221 0"/>
      <mass value="0.055"/>
      <inertia ixx="0.000021370" ixy="0" ixz="0" iyy="0.000009966" iyz="0" izz="0.000021370"/>
    </inertial>
  </link>
  <joint name="upper_left_wheel_joint" type="continuous">
    <origin rpy="0 0 0" xyz="0 0.042 0"/>
    <parent link="upper_left_wheel_shaft"/>
    <child link="upper_left_wheel"/>
    <axis xyz="0 1 0"/>
  </joint>
  <link name="upper_left_wheel">
    <visual>
      <origin rpy="0 0 0" xyz="0 0 0"/>
      <geometry>
        <mesh filename="package://artbot_pkg/meshes/mecanum_wheel_left.STL" scale="0.001 0.001 0.001"/>
      </geometry>
      <material name="light_grey"/>
    </visual>
    <collision>
      <origin rpy="1.57079632679 0 0" xyz="0 0 0"/>
      <geometry>
        <cylinder length="0.0505" radius="0.05"/>
      </geometry>
    </collision>
    <inertial>
      <origin rpy="0 0 0" xyz="0.0 0.0 0.0"/>
      <mass value="0.3844"/>
      <!-- Inertia based on cylinder -->
      <inertia ixx="0.000324824" ixy="0" ixz="0" iyy="0.000480000" iyz="0" izz="0.000324824"/>
    </inertial>
  </link>
  <joint name="lower_left_wheel_joint" type="continuous">
    <origin rpy="0 0 0" xyz="0 0.042 0"/>
    <parent link="lower_left_wheel_shaft"/>
    <child link="lower_left_wheel"/>
    <axis xyz="0 1 0"/>
  </joint>
  <link name="lower_left_wheel">
    <visual>
      <origin rpy="0 0 0" xyz="0 0 0"/>
      <geometry>
        <mesh filename="package://artbot_pkg/meshes/mecanum_wheel_right.STL" scale="0.001 0.001 0.001"/>
      </geometry>
      <material name="light_grey"/>
    </visual>
    <collision>
      <origin rpy="1.57079632679 0 0" xyz="0 0 0"/>
      <geometry>
        <cylinder length="0.0505" radius="0.05"/>
      </geometry>
    </collision>
    <inertial>
      <origin rpy="0 0 0" xyz="0.0 0.0 0.0"/>
      <mass value="0.3844"/>
      <!-- Inertia based on cylinder -->
      <inertia ixx="0.000324824" ixy="0" ixz="0" iyy="0.000480000" iyz="0" izz="0.000324824"/>
    </inertial>
  </link>
  <joint name="upper_right_wheel_joint" type="continuous">
    <origin rpy="0 0 0" xyz="0 0.042 0"/>
    <parent link="upper_right_wheel_shaft"/>
    <child link="upper_right_wheel"/>
    <axis xyz="0 1 0"/>
  </joint>
  <link name="upper_right_wheel">
    <visual>
      <origin rpy="0 0 0" xyz="0 0 0"/>
      <geometry>
        <mesh filename="package://artbot_pkg/meshes/mecanum_wheel_right.STL" scale="0.001 0.001 0.001"/>
      </geometry>
      <material name="light_grey"/>
    </visual>
    <collision>
      <origin rpy="1.57079632679 0 0" xyz="0 0 0"/>
      <geometry>
        <cylinder length="0.0505" radius="0.05"/>
      </geometry>
    </collision>
    <inertial>
      <origin rpy="0 0 0" xyz="0.0 0.0 0.0"/>
      <mass value="0.3844"/>
      <!-- Inertia based on cylinder -->
      <inertia ixx="0.000324824" ixy="0" ixz="0" iyy="0.000480000" iyz="0" izz="0.000324824"/>
    </inertial>
  </link>
  <joint name="lower_right_wheel_joint" type="continuous">
    <origin rpy="0 0 0" xyz="0 0.042 0"/>
    <parent link="lower_right_wheel_shaft"/>
    <child link="lower_right_wheel"/>
    <axis xyz="0 1 0"/>
  </joint>
  <link name="lower_right_wheel">
    <visual>
      <origin rpy="0 0 0" xyz="0 0 0"/>
      <geometry>
        <mesh filename="package://artbot_pkg/meshes/mecanum_wheel_left.STL" scale="0.001 0.001 0.001"/>
      </geometry>
      <material name="light_grey"/>
    </visual>
    <collision>
      <origin rpy="1.57079632679 0 0" xyz="0 0 0"/>
      <geometry>
        <cylinder length="0.0505" radius="0.05"/>
      </geometry>
    </collision>
    <inertial>
      <origin rpy="0 0 0" xyz="0.0 0.0 0.0"/>
      <mass value="0.3844"/>
      <!-- Inertia based on cylinder -->
      <inertia ixx="0.000324824" ixy="0" ixz="0" iyy="0.000480000" iyz="0" izz="0.000324824"/>
    </inertial>
  </link>
  <gazebo>
    <!--<plugin name="gazebo_ros_control" filename="libgazebo_ros_control.so">
      <robotNamespace>/</robotNamespace>
    </plugin>-->
    <plugin filename="libnexus_ros_force_based_move.so" name="art_ros_force_based_move">
      <commandTopic>cmd_vel</commandTopic>
      <odometryTopic>odom</odometryTopic>
      <odometryFrame>odom</odometryFrame>
      <odometryRate>25.0</odometryRate>
      <robotBaseFrame>base_footprint</robotBaseFrame>
      <cmdVelTimeOut>0.25</cmdVelTimeOut>
      <publishOdometryTf>0</publishOdometryTf>
      <yaw_velocity_p_gain>1.0</yaw_velocity_p_gain>
      <x_velocity_p_gain>15.0</x_velocity_p_gain>
      <y_velocity_p_gain>15.0</y_velocity_p_gain>
      <max_x_velocity>0.6</max_x_velocity>
      <max_y_velocity>0.6</max_y_velocity>
      <max_yaw_velocity>0.5</max_yaw_velocity>
    </plugin>
  </gazebo>
  <!-- All static links get collapsed down to base_link in Gazebo, so that's
       the one to apply the colour to (in Gazebo 5+). -->
  <gazebo reference="base_footprint">
    <material>Gazebo/Yellow</material>
    <gravity>true</gravity>
  </gazebo>
  <gazebo reference="base_link">
    <material>Gazebo/Yellow</material>
  </gazebo>

  <gazebo reference="upper_left_wheel_shaft">
    <material>Gazebo/Black</material>
  </gazebo>
  <gazebo reference="lower_left_wheel_shaft">
    <material>Gazebo/Black</material>
  </gazebo>
  <gazebo reference="upper_right_wheel_shaft">
    <material>Gazebo/Black</material>
  </gazebo>
  <gazebo reference="lower_right_wheel_shaft">
    <material>Gazebo/Black</material>
  </gazebo>
  <!-- Wheel friction to zero, as movement is handled by applying forces at the body level. -->
  <gazebo reference="upper_left_wheel">
    <material>Gazebo/Grey</material>
    <mu1>0.0</mu1>
    <mu2>0.0</mu2>
  </gazebo>
  <gazebo reference="lower_left_wheel">
    <material>Gazebo/Grey</material>
    <mu1>0.0</mu1>
    <mu2>0.0</mu2>
  </gazebo>
  <gazebo reference="upper_right_wheel">
    <material>Gazebo/Grey</material>
    <mu1>0.0</mu1>
    <mu2>0.0</mu2>
  </gazebo>
  <gazebo reference="lower_right_wheel">
    <material>Gazebo/Grey</material>
    <mu1>0.0</mu1>
    <mu2>0.0</mu2>
  </gazebo>
</robot>

